<?xml version="1.0" encoding="UTF-8"?>
<!-- Generated by org.testng.reporters.JUnitReportReporter -->
<testsuite skipped="0" hostname="CSS-D-196" name="com.concerto.vegaah.test.scenarios.apiTransactions.CardedTransPGHosted" tests="20" failures="9" timestamp="26 Aug 2020 09:30:38 GMT" time="71.258" errors="2">
  <testcase name="transaction" time="19.815" classname="com.concerto.vegaah.test.scenarios.apiTransactions.CardedTransPGHosted"/>
  <testcase name="transaction" time="1.292" classname="com.concerto.vegaah.test.scenarios.apiTransactions.CardedTransPGHosted"/>
  <testcase name="transaction" time="1.128" classname="com.concerto.vegaah.test.scenarios.apiTransactions.CardedTransPGHosted"/>
  <testcase name="transaction" time="1.152" classname="com.concerto.vegaah.test.scenarios.apiTransactions.CardedTransPGHosted"/>
  <testcase name="transaction" time="0.988" classname="com.concerto.vegaah.test.scenarios.apiTransactions.CardedTransPGHosted">
    <error type="java.lang.IndexOutOfBoundsException" message="Index: 0, Size: 0">
      <![CDATA[java.lang.IndexOutOfBoundsException: Index: 0, Size: 0
at java.util.ArrayList.rangeCheck(Unknown Source)
at java.util.ArrayList.get(Unknown Source)
at com.concerto.vegaah.db.methods.ValidateTransactionStatus.QueryApplicationConfig(ValidateTransactionStatus.java:49)
at com.concerto.vegaah.test.scenarios.apiTransactions.CardedTransPGHosted.transaction(CardedTransPGHosted.java:105)
at sun.reflect.NativeMethodAccessorImpl.invoke0(Native Method)
at sun.reflect.NativeMethodAccessorImpl.invoke(Unknown Source)
at sun.reflect.DelegatingMethodAccessorImpl.invoke(Unknown Source)
at java.lang.reflect.Method.invoke(Unknown Source)
at org.testng.internal.MethodInvocationHelper.invokeMethod(MethodInvocationHelper.java:124)
at org.testng.internal.Invoker.invokeMethod(Invoker.java:583)
at org.testng.internal.Invoker.invokeTestMethod(Invoker.java:719)
at org.testng.internal.Invoker.invokeTestMethods(Invoker.java:989)
at org.testng.internal.TestMethodWorker.invokeTestMethods(TestMethodWorker.java:125)
at org.testng.internal.TestMethodWorker.run(TestMethodWorker.java:109)
at org.testng.TestRunner.privateRun(TestRunner.java:648)
at org.testng.TestRunner.run(TestRunner.java:505)
at org.testng.SuiteRunner.runTest(SuiteRunner.java:455)
at org.testng.SuiteRunner.access$000(SuiteRunner.java:40)
at org.testng.SuiteRunner$SuiteWorker.run(SuiteRunner.java:489)
at org.testng.internal.thread.ThreadUtil$1.call(ThreadUtil.java:52)
at java.util.concurrent.FutureTask.run(Unknown Source)
at java.util.concurrent.ThreadPoolExecutor.runWorker(Unknown Source)
at java.util.concurrent.ThreadPoolExecutor$Worker.run(Unknown Source)
at java.lang.Thread.run(Unknown Source)
]]>
    </error>
  </testcase> <!-- transaction -->
  <testcase name="transaction" time="0.827" classname="com.concerto.vegaah.test.scenarios.apiTransactions.CardedTransPGHosted"/>
  <testcase name="transaction" time="5.748" classname="com.concerto.vegaah.test.scenarios.apiTransactions.CardedTransPGHosted">
    <failure type="java.lang.AssertionError" message="java.lang.AssertionError: Correct Response Code of 636 is displayed for payment test of type Transaction has been Voided , Multiple voids not allowed. expected [636] but found [512]java.lang.AssertionError: Correct Response Code of 636 is displayed for payment test of type Transaction has been Voided , Multiple voids not allowed. expected [636] but found [512]">
      <![CDATA[java.lang.AssertionError: java.lang.AssertionError: Correct Response Code of 636 is displayed for payment test of type Transaction has been Voided , Multiple voids not allowed. expected [636] but found [512]java.lang.AssertionError: Correct Response Code of 636 is displayed for payment test of type Transaction has been Voided , Multiple voids not allowed. expected [636] but found [512]
at org.testng.Assert.fail(Assert.java:96)
at com.concerto.common.utilities.Asserts.AssertAll(Asserts.java:191)
at com.concerto.vegaah.test.scenarios.apiTransactions.CardedTransPGHosted.transaction(CardedTransPGHosted.java:184)
at sun.reflect.NativeMethodAccessorImpl.invoke0(Native Method)
at sun.reflect.NativeMethodAccessorImpl.invoke(Unknown Source)
at sun.reflect.DelegatingMethodAccessorImpl.invoke(Unknown Source)
at java.lang.reflect.Method.invoke(Unknown Source)
at org.testng.internal.MethodInvocationHelper.invokeMethod(MethodInvocationHelper.java:124)
at org.testng.internal.Invoker.invokeMethod(Invoker.java:583)
at org.testng.internal.Invoker.invokeTestMethod(Invoker.java:719)
at org.testng.internal.Invoker.invokeTestMethods(Invoker.java:989)
at org.testng.internal.TestMethodWorker.invokeTestMethods(TestMethodWorker.java:125)
at org.testng.internal.TestMethodWorker.run(TestMethodWorker.java:109)
at org.testng.TestRunner.privateRun(TestRunner.java:648)
at org.testng.TestRunner.run(TestRunner.java:505)
at org.testng.SuiteRunner.runTest(SuiteRunner.java:455)
at org.testng.SuiteRunner.access$000(SuiteRunner.java:40)
at org.testng.SuiteRunner$SuiteWorker.run(SuiteRunner.java:489)
at org.testng.internal.thread.ThreadUtil$1.call(ThreadUtil.java:52)
at java.util.concurrent.FutureTask.run(Unknown Source)
at java.util.concurrent.ThreadPoolExecutor.runWorker(Unknown Source)
at java.util.concurrent.ThreadPoolExecutor$Worker.run(Unknown Source)
at java.lang.Thread.run(Unknown Source)
]]>
    </failure>
  </testcase> <!-- transaction -->
  <testcase name="transaction" time="1.095" classname="com.concerto.vegaah.test.scenarios.apiTransactions.CardedTransPGHosted"/>
  <testcase name="transaction" time="3.763" classname="com.concerto.vegaah.test.scenarios.apiTransactions.CardedTransPGHosted">
    <failure type="java.lang.AssertionError" message="java.lang.AssertionError: Correct Response Code of 000 is displayed for payment test of type Transaction successful-Refund(Purchase) expected [000] but found [644]">
      <![CDATA[java.lang.AssertionError: java.lang.AssertionError: Correct Response Code of 000 is displayed for payment test of type Transaction successful-Refund(Purchase) expected [000] but found [644]
at org.testng.Assert.fail(Assert.java:96)
at com.concerto.common.utilities.Asserts.AssertAll(Asserts.java:191)
at com.concerto.vegaah.test.scenarios.apiTransactions.CardedTransPGHosted.transaction(CardedTransPGHosted.java:184)
at sun.reflect.GeneratedMethodAccessor144.invoke(Unknown Source)
at sun.reflect.DelegatingMethodAccessorImpl.invoke(Unknown Source)
at java.lang.reflect.Method.invoke(Unknown Source)
at org.testng.internal.MethodInvocationHelper.invokeMethod(MethodInvocationHelper.java:124)
at org.testng.internal.Invoker.invokeMethod(Invoker.java:583)
at org.testng.internal.Invoker.invokeTestMethod(Invoker.java:719)
at org.testng.internal.Invoker.invokeTestMethods(Invoker.java:989)
at org.testng.internal.TestMethodWorker.invokeTestMethods(TestMethodWorker.java:125)
at org.testng.internal.TestMethodWorker.run(TestMethodWorker.java:109)
at org.testng.TestRunner.privateRun(TestRunner.java:648)
at org.testng.TestRunner.run(TestRunner.java:505)
at org.testng.SuiteRunner.runTest(SuiteRunner.java:455)
at org.testng.SuiteRunner.access$000(SuiteRunner.java:40)
at org.testng.SuiteRunner$SuiteWorker.run(SuiteRunner.java:489)
at org.testng.internal.thread.ThreadUtil$1.call(ThreadUtil.java:52)
at java.util.concurrent.FutureTask.run(Unknown Source)
at java.util.concurrent.ThreadPoolExecutor.runWorker(Unknown Source)
at java.util.concurrent.ThreadPoolExecutor$Worker.run(Unknown Source)
at java.lang.Thread.run(Unknown Source)
]]>
    </failure>
  </testcase> <!-- transaction -->
  <testcase name="transaction" time="1.011" classname="com.concerto.vegaah.test.scenarios.apiTransactions.CardedTransPGHosted">
    <failure type="java.lang.AssertionError" message="java.lang.AssertionError: Correct Response Code of 000 is displayed for payment test of type Transaction successful-Void Purchase expected [000] but found [671]">
      <![CDATA[java.lang.AssertionError: java.lang.AssertionError: Correct Response Code of 000 is displayed for payment test of type Transaction successful-Void Purchase expected [000] but found [671]
at org.testng.Assert.fail(Assert.java:96)
at com.concerto.common.utilities.Asserts.AssertAll(Asserts.java:191)
at com.concerto.vegaah.test.scenarios.apiTransactions.CardedTransPGHosted.transaction(CardedTransPGHosted.java:184)
at sun.reflect.GeneratedMethodAccessor144.invoke(Unknown Source)
at sun.reflect.DelegatingMethodAccessorImpl.invoke(Unknown Source)
at java.lang.reflect.Method.invoke(Unknown Source)
at org.testng.internal.MethodInvocationHelper.invokeMethod(MethodInvocationHelper.java:124)
at org.testng.internal.Invoker.invokeMethod(Invoker.java:583)
at org.testng.internal.Invoker.invokeTestMethod(Invoker.java:719)
at org.testng.internal.Invoker.invokeTestMethods(Invoker.java:989)
at org.testng.internal.TestMethodWorker.invokeTestMethods(TestMethodWorker.java:125)
at org.testng.internal.TestMethodWorker.run(TestMethodWorker.java:109)
at org.testng.TestRunner.privateRun(TestRunner.java:648)
at org.testng.TestRunner.run(TestRunner.java:505)
at org.testng.SuiteRunner.runTest(SuiteRunner.java:455)
at org.testng.SuiteRunner.access$000(SuiteRunner.java:40)
at org.testng.SuiteRunner$SuiteWorker.run(SuiteRunner.java:489)
at org.testng.internal.thread.ThreadUtil$1.call(ThreadUtil.java:52)
at java.util.concurrent.FutureTask.run(Unknown Source)
at java.util.concurrent.ThreadPoolExecutor.runWorker(Unknown Source)
at java.util.concurrent.ThreadPoolExecutor$Worker.run(Unknown Source)
at java.lang.Thread.run(Unknown Source)
]]>
    </failure>
  </testcase> <!-- transaction -->
  <testcase name="transaction" time="0.961" classname="com.concerto.vegaah.test.scenarios.apiTransactions.CardedTransPGHosted"/>
  <testcase name="transaction" time="0.948" classname="com.concerto.vegaah.test.scenarios.apiTransactions.CardedTransPGHosted"/>
  <testcase name="transaction" time="5.130" classname="com.concerto.vegaah.test.scenarios.apiTransactions.CardedTransPGHosted">
    <failure type="java.lang.AssertionError" message="java.lang.AssertionError: Correct Response Code of 635 is displayed for payment test of type Transaction has been Captured, Multiple captures not allowed. expected [635] but found [512]">
      <![CDATA[java.lang.AssertionError: java.lang.AssertionError: Correct Response Code of 635 is displayed for payment test of type Transaction has been Captured, Multiple captures not allowed. expected [635] but found [512]
at org.testng.Assert.fail(Assert.java:96)
at com.concerto.common.utilities.Asserts.AssertAll(Asserts.java:191)
at com.concerto.vegaah.test.scenarios.apiTransactions.CardedTransPGHosted.transaction(CardedTransPGHosted.java:184)
at sun.reflect.NativeMethodAccessorImpl.invoke0(Native Method)
at sun.reflect.NativeMethodAccessorImpl.invoke(Unknown Source)
at sun.reflect.DelegatingMethodAccessorImpl.invoke(Unknown Source)
at java.lang.reflect.Method.invoke(Unknown Source)
at org.testng.internal.MethodInvocationHelper.invokeMethod(MethodInvocationHelper.java:124)
at org.testng.internal.Invoker.invokeMethod(Invoker.java:583)
at org.testng.internal.Invoker.invokeTestMethod(Invoker.java:719)
at org.testng.internal.Invoker.invokeTestMethods(Invoker.java:989)
at org.testng.internal.TestMethodWorker.invokeTestMethods(TestMethodWorker.java:125)
at org.testng.internal.TestMethodWorker.run(TestMethodWorker.java:109)
at org.testng.TestRunner.privateRun(TestRunner.java:648)
at org.testng.TestRunner.run(TestRunner.java:505)
at org.testng.SuiteRunner.runTest(SuiteRunner.java:455)
at org.testng.SuiteRunner.access$000(SuiteRunner.java:40)
at org.testng.SuiteRunner$SuiteWorker.run(SuiteRunner.java:489)
at org.testng.internal.thread.ThreadUtil$1.call(ThreadUtil.java:52)
at java.util.concurrent.FutureTask.run(Unknown Source)
at java.util.concurrent.ThreadPoolExecutor.runWorker(Unknown Source)
at java.util.concurrent.ThreadPoolExecutor$Worker.run(Unknown Source)
at java.lang.Thread.run(Unknown Source)
]]>
    </failure>
  </testcase> <!-- transaction -->
  <testcase name="transaction" time="0.893" classname="com.concerto.vegaah.test.scenarios.apiTransactions.CardedTransPGHosted"/>
  <testcase name="transaction" time="5.974" classname="com.concerto.vegaah.test.scenarios.apiTransactions.CardedTransPGHosted">
    <failure type="java.lang.AssertionError" message="java.lang.AssertionError: Correct Response Code of 000 is displayed for payment test of type Transaction successful-Void Refund(Purchase) expected [000] but found [512]java.lang.AssertionError: Correct Response Code of 000 is displayed for payment test of type Transaction successful-Void Refund(Purchase) expected [000] but found [512]java.lang.AssertionError: Correct Response Code of 000 is displayed for payment test of type Transaction successful-Void Refund(Purchase) expected [000] but found [512]">
      <![CDATA[java.lang.AssertionError: java.lang.AssertionError: Correct Response Code of 000 is displayed for payment test of type Transaction successful-Void Refund(Purchase) expected [000] but found [512]java.lang.AssertionError: Correct Response Code of 000 is displayed for payment test of type Transaction successful-Void Refund(Purchase) expected [000] but found [512]java.lang.AssertionError: Correct Response Code of 000 is displayed for payment test of type Transaction successful-Void Refund(Purchase) expected [000] but found [512]
at org.testng.Assert.fail(Assert.java:96)
at com.concerto.common.utilities.Asserts.AssertAll(Asserts.java:191)
at com.concerto.vegaah.test.scenarios.apiTransactions.CardedTransPGHosted.transaction(CardedTransPGHosted.java:184)
at sun.reflect.GeneratedMethodAccessor144.invoke(Unknown Source)
at sun.reflect.DelegatingMethodAccessorImpl.invoke(Unknown Source)
at java.lang.reflect.Method.invoke(Unknown Source)
at org.testng.internal.MethodInvocationHelper.invokeMethod(MethodInvocationHelper.java:124)
at org.testng.internal.Invoker.invokeMethod(Invoker.java:583)
at org.testng.internal.Invoker.invokeTestMethod(Invoker.java:719)
at org.testng.internal.Invoker.invokeTestMethods(Invoker.java:989)
at org.testng.internal.TestMethodWorker.invokeTestMethods(TestMethodWorker.java:125)
at org.testng.internal.TestMethodWorker.run(TestMethodWorker.java:109)
at org.testng.TestRunner.privateRun(TestRunner.java:648)
at org.testng.TestRunner.run(TestRunner.java:505)
at org.testng.SuiteRunner.runTest(SuiteRunner.java:455)
at org.testng.SuiteRunner.access$000(SuiteRunner.java:40)
at org.testng.SuiteRunner$SuiteWorker.run(SuiteRunner.java:489)
at org.testng.internal.thread.ThreadUtil$1.call(ThreadUtil.java:52)
at java.util.concurrent.FutureTask.run(Unknown Source)
at java.util.concurrent.ThreadPoolExecutor.runWorker(Unknown Source)
at java.util.concurrent.ThreadPoolExecutor$Worker.run(Unknown Source)
at java.lang.Thread.run(Unknown Source)
]]>
    </failure>
  </testcase> <!-- transaction -->
  <testcase name="transaction" time="0.856" classname="com.concerto.vegaah.test.scenarios.apiTransactions.CardedTransPGHosted">
    <error type="java.lang.IndexOutOfBoundsException" message="Index: 0, Size: 0">
      <![CDATA[java.lang.IndexOutOfBoundsException: Index: 0, Size: 0
at java.util.ArrayList.rangeCheck(Unknown Source)
at java.util.ArrayList.get(Unknown Source)
at com.concerto.vegaah.db.methods.ValidateTransactionStatus.QueryApplicationConfig(ValidateTransactionStatus.java:49)
at com.concerto.vegaah.test.scenarios.apiTransactions.CardedTransPGHosted.transaction(CardedTransPGHosted.java:105)
at sun.reflect.NativeMethodAccessorImpl.invoke0(Native Method)
at sun.reflect.NativeMethodAccessorImpl.invoke(Unknown Source)
at sun.reflect.DelegatingMethodAccessorImpl.invoke(Unknown Source)
at java.lang.reflect.Method.invoke(Unknown Source)
at org.testng.internal.MethodInvocationHelper.invokeMethod(MethodInvocationHelper.java:124)
at org.testng.internal.Invoker.invokeMethod(Invoker.java:583)
at org.testng.internal.Invoker.invokeTestMethod(Invoker.java:719)
at org.testng.internal.Invoker.invokeTestMethods(Invoker.java:989)
at org.testng.internal.TestMethodWorker.invokeTestMethods(TestMethodWorker.java:125)
at org.testng.internal.TestMethodWorker.run(TestMethodWorker.java:109)
at org.testng.TestRunner.privateRun(TestRunner.java:648)
at org.testng.TestRunner.run(TestRunner.java:505)
at org.testng.SuiteRunner.runTest(SuiteRunner.java:455)
at org.testng.SuiteRunner.access$000(SuiteRunner.java:40)
at org.testng.SuiteRunner$SuiteWorker.run(SuiteRunner.java:489)
at org.testng.internal.thread.ThreadUtil$1.call(ThreadUtil.java:52)
at java.util.concurrent.FutureTask.run(Unknown Source)
at java.util.concurrent.ThreadPoolExecutor.runWorker(Unknown Source)
at java.util.concurrent.ThreadPoolExecutor$Worker.run(Unknown Source)
at java.lang.Thread.run(Unknown Source)
]]>
    </error>
  </testcase> <!-- transaction -->
  <testcase name="transaction" time="3.993" classname="com.concerto.vegaah.test.scenarios.apiTransactions.CardedTransPGHosted">
    <failure type="java.lang.AssertionError" message="java.lang.AssertionError: Correct Response Code of 000 is displayed for payment test of type Transaction successful-Refund(Pre-auth) expected [000] but found [644]">
      <![CDATA[java.lang.AssertionError: java.lang.AssertionError: Correct Response Code of 000 is displayed for payment test of type Transaction successful-Refund(Pre-auth) expected [000] but found [644]
at org.testng.Assert.fail(Assert.java:96)
at com.concerto.common.utilities.Asserts.AssertAll(Asserts.java:191)
at com.concerto.vegaah.test.scenarios.apiTransactions.CardedTransPGHosted.transaction(CardedTransPGHosted.java:184)
at sun.reflect.NativeMethodAccessorImpl.invoke0(Native Method)
at sun.reflect.NativeMethodAccessorImpl.invoke(Unknown Source)
at sun.reflect.DelegatingMethodAccessorImpl.invoke(Unknown Source)
at java.lang.reflect.Method.invoke(Unknown Source)
at org.testng.internal.MethodInvocationHelper.invokeMethod(MethodInvocationHelper.java:124)
at org.testng.internal.Invoker.invokeMethod(Invoker.java:583)
at org.testng.internal.Invoker.invokeTestMethod(Invoker.java:719)
at org.testng.internal.Invoker.invokeTestMethods(Invoker.java:989)
at org.testng.internal.TestMethodWorker.invokeTestMethods(TestMethodWorker.java:125)
at org.testng.internal.TestMethodWorker.run(TestMethodWorker.java:109)
at org.testng.TestRunner.privateRun(TestRunner.java:648)
at org.testng.TestRunner.run(TestRunner.java:505)
at org.testng.SuiteRunner.runTest(SuiteRunner.java:455)
at org.testng.SuiteRunner.access$000(SuiteRunner.java:40)
at org.testng.SuiteRunner$SuiteWorker.run(SuiteRunner.java:489)
at org.testng.internal.thread.ThreadUtil$1.call(ThreadUtil.java:52)
at java.util.concurrent.FutureTask.run(Unknown Source)
at java.util.concurrent.ThreadPoolExecutor.runWorker(Unknown Source)
at java.util.concurrent.ThreadPoolExecutor$Worker.run(Unknown Source)
at java.lang.Thread.run(Unknown Source)
]]>
    </failure>
  </testcase> <!-- transaction -->
  <testcase name="transaction" time="5.913" classname="com.concerto.vegaah.test.scenarios.apiTransactions.CardedTransPGHosted">
    <failure type="java.lang.AssertionError" message="java.lang.AssertionError: Correct Response Code of 000 is displayed for payment test of type Transaction successful-Void Refund(Pre-auth) expected [000] but found [512]java.lang.AssertionError: Correct Response Code of 000 is displayed for payment test of type Transaction successful-Void Refund(Pre-auth) expected [000] but found [512]java.lang.AssertionError: Correct Response Code of 000 is displayed for payment test of type Transaction successful-Void Refund(Pre-auth) expected [000] but found [512]">
      <![CDATA[java.lang.AssertionError: java.lang.AssertionError: Correct Response Code of 000 is displayed for payment test of type Transaction successful-Void Refund(Pre-auth) expected [000] but found [512]java.lang.AssertionError: Correct Response Code of 000 is displayed for payment test of type Transaction successful-Void Refund(Pre-auth) expected [000] but found [512]java.lang.AssertionError: Correct Response Code of 000 is displayed for payment test of type Transaction successful-Void Refund(Pre-auth) expected [000] but found [512]
at org.testng.Assert.fail(Assert.java:96)
at com.concerto.common.utilities.Asserts.AssertAll(Asserts.java:191)
at com.concerto.vegaah.test.scenarios.apiTransactions.CardedTransPGHosted.transaction(CardedTransPGHosted.java:184)
at sun.reflect.NativeMethodAccessorImpl.invoke0(Native Method)
at sun.reflect.NativeMethodAccessorImpl.invoke(Unknown Source)
at sun.reflect.DelegatingMethodAccessorImpl.invoke(Unknown Source)
at java.lang.reflect.Method.invoke(Unknown Source)
at org.testng.internal.MethodInvocationHelper.invokeMethod(MethodInvocationHelper.java:124)
at org.testng.internal.Invoker.invokeMethod(Invoker.java:583)
at org.testng.internal.Invoker.invokeTestMethod(Invoker.java:719)
at org.testng.internal.Invoker.invokeTestMethods(Invoker.java:989)
at org.testng.internal.TestMethodWorker.invokeTestMethods(TestMethodWorker.java:125)
at org.testng.internal.TestMethodWorker.run(TestMethodWorker.java:109)
at org.testng.TestRunner.privateRun(TestRunner.java:648)
at org.testng.TestRunner.run(TestRunner.java:505)
at org.testng.SuiteRunner.runTest(SuiteRunner.java:455)
at org.testng.SuiteRunner.access$000(SuiteRunner.java:40)
at org.testng.SuiteRunner$SuiteWorker.run(SuiteRunner.java:489)
at org.testng.internal.thread.ThreadUtil$1.call(ThreadUtil.java:52)
at java.util.concurrent.FutureTask.run(Unknown Source)
at java.util.concurrent.ThreadPoolExecutor.runWorker(Unknown Source)
at java.util.concurrent.ThreadPoolExecutor$Worker.run(Unknown Source)
at java.lang.Thread.run(Unknown Source)
]]>
    </failure>
  </testcase> <!-- transaction -->
  <testcase name="transaction" time="4.473" classname="com.concerto.vegaah.test.scenarios.apiTransactions.CardedTransPGHosted">
    <failure type="java.lang.AssertionError" message="java.lang.AssertionError: Correct Response Code of 000 is displayed for payment test of type Transaction successful-Capture expected [000] but found [512]">
      <![CDATA[java.lang.AssertionError: java.lang.AssertionError: Correct Response Code of 000 is displayed for payment test of type Transaction successful-Capture expected [000] but found [512]
at org.testng.Assert.fail(Assert.java:96)
at com.concerto.common.utilities.Asserts.AssertAll(Asserts.java:191)
at com.concerto.vegaah.test.scenarios.apiTransactions.CardedTransPGHosted.transaction(CardedTransPGHosted.java:184)
at sun.reflect.NativeMethodAccessorImpl.invoke0(Native Method)
at sun.reflect.NativeMethodAccessorImpl.invoke(Unknown Source)
at sun.reflect.DelegatingMethodAccessorImpl.invoke(Unknown Source)
at java.lang.reflect.Method.invoke(Unknown Source)
at org.testng.internal.MethodInvocationHelper.invokeMethod(MethodInvocationHelper.java:124)
at org.testng.internal.Invoker.invokeMethod(Invoker.java:583)
at org.testng.internal.Invoker.invokeTestMethod(Invoker.java:719)
at org.testng.internal.Invoker.invokeTestMethods(Invoker.java:989)
at org.testng.internal.TestMethodWorker.invokeTestMethods(TestMethodWorker.java:125)
at org.testng.internal.TestMethodWorker.run(TestMethodWorker.java:109)
at org.testng.TestRunner.privateRun(TestRunner.java:648)
at org.testng.TestRunner.run(TestRunner.java:505)
at org.testng.SuiteRunner.runTest(SuiteRunner.java:455)
at org.testng.SuiteRunner.access$000(SuiteRunner.java:40)
at org.testng.SuiteRunner$SuiteWorker.run(SuiteRunner.java:489)
at org.testng.internal.thread.ThreadUtil$1.call(ThreadUtil.java:52)
at java.util.concurrent.FutureTask.run(Unknown Source)
at java.util.concurrent.ThreadPoolExecutor.runWorker(Unknown Source)
at java.util.concurrent.ThreadPoolExecutor$Worker.run(Unknown Source)
at java.lang.Thread.run(Unknown Source)
]]>
    </failure>
  </testcase> <!-- transaction -->
  <testcase name="transaction" time="5.298" classname="com.concerto.vegaah.test.scenarios.apiTransactions.CardedTransPGHosted">
    <failure type="java.lang.AssertionError" message="java.lang.AssertionError: Correct Response Code of 000 is displayed for payment test of type Transaction successful-Void Pre-auth expected [000] but found [512]">
      <![CDATA[java.lang.AssertionError: java.lang.AssertionError: Correct Response Code of 000 is displayed for payment test of type Transaction successful-Void Pre-auth expected [000] but found [512]
at org.testng.Assert.fail(Assert.java:96)
at com.concerto.common.utilities.Asserts.AssertAll(Asserts.java:191)
at com.concerto.vegaah.test.scenarios.apiTransactions.CardedTransPGHosted.transaction(CardedTransPGHosted.java:184)
at sun.reflect.GeneratedMethodAccessor144.invoke(Unknown Source)
at sun.reflect.DelegatingMethodAccessorImpl.invoke(Unknown Source)
at java.lang.reflect.Method.invoke(Unknown Source)
at org.testng.internal.MethodInvocationHelper.invokeMethod(MethodInvocationHelper.java:124)
at org.testng.internal.Invoker.invokeMethod(Invoker.java:583)
at org.testng.internal.Invoker.invokeTestMethod(Invoker.java:719)
at org.testng.internal.Invoker.invokeTestMethods(Invoker.java:989)
at org.testng.internal.TestMethodWorker.invokeTestMethods(TestMethodWorker.java:125)
at org.testng.internal.TestMethodWorker.run(TestMethodWorker.java:109)
at org.testng.TestRunner.privateRun(TestRunner.java:648)
at org.testng.TestRunner.run(TestRunner.java:505)
at org.testng.SuiteRunner.runTest(SuiteRunner.java:455)
at org.testng.SuiteRunner.access$000(SuiteRunner.java:40)
at org.testng.SuiteRunner$SuiteWorker.run(SuiteRunner.java:489)
at org.testng.internal.thread.ThreadUtil$1.call(ThreadUtil.java:52)
at java.util.concurrent.FutureTask.run(Unknown Source)
at java.util.concurrent.ThreadPoolExecutor.runWorker(Unknown Source)
at java.util.concurrent.ThreadPoolExecutor$Worker.run(Unknown Source)
at java.lang.Thread.run(Unknown Source)
]]>
    </failure>
  </testcase> <!-- transaction -->
</testsuite> <!-- com.concerto.vegaah.test.scenarios.apiTransactions.CardedTransPGHosted -->
